<robot name="GeneratedRobot">

    <material name="white">
        <color rgba="1 1 1 1" />
    </material>

    <material name="orange">
        <color rgba="1 0.3 0.1 1"/>
    </material>

    <material name="blue">
        <color rgba="0.2 0.2 1 1"/>
    </material>

    <material name="black">
        <color rgba="0 0 0 1"/>
    </material>

    <material name="red">
        <color rgba="1 0 0 1"/>
    </material>

    <link name = "base_link">
        <origin xyz="0.0 0.0 0.08" rpy="0.0 0.0 0.0"/>
    </link>

    <joint name="chassis_joint" type="fixed">
        <origin xyz="0.0 0.0 0.0" rpy="0.0 0.0 0.0"/>
        <parent link="base_link"/>
        <child link="chassis"/>
    </joint>

    <!-- CHASSIS LINK -->

    <link name="chassis">
        <visual>
            <origin xyz="0 0 0.05" rpy="0 0 0" />
            <geometry>
                <box size="0.15 0.3 0.12" />
            </geometry>
            <material name="orange"/>
        </visual>
        <visual>
            <origin xyz="0.0 0.0 0.1" rpy="0.0 0.0 0.0"/>
            <geometry>
                <box size="0.25 0.3 0.08"/>
            </geometry>
            <material name = "orange"/>
        </visual>
        <collision>
            <origin xyz="0 0 0.08" rpy="0 0 0" />
            <geometry>
                <box size="0.18 0.3 0.15" />
            </geometry>
        </collision>
        <collision>
            <origin xyz="0.0 0.0 0.1" rpy="0.0 0.0 0.0"/>
            <geometry>
                <box size="0.25 0.3 0.08"/>
            </geometry>
            <material name = "orange"/>
        </collision>
        <inertial>
            <origin xyz="0 0 0.08" rpy="0 0 0" />
            <mass value="7"/>
            <inertia ixx="0.061" ixy="0" ixz="0" iyy="0.022" iyz="0" izz="0.066" />
        </inertial>
    </link>

    <gazebo reference="chassis">
        <material>Gazebo/Orange</material>
    </gazebo>

    <joint name="base_footprint_joint" type="fixed">
        <parent link="base_link"/>
        <child link="base_footprint"/>
        <origin xyz="0.0 0.0 0.0" rpy="0.0 0.0 0.0"/>
    </joint>

    <link name="base_footprint">
        
    </link>



    <!-- LEFT WHEEL -->

    <link name="left_wheel">
        <visual>
            <origin xyz="0 0 0" rpy="0 0 0" />
            <geometry>
                <cylinder radius="0.08499999999999996" length="0.0635" />
            </geometry>
            <material name="white"/>
        </visual>
        <collision>
            <origin xyz="0 0 0" rpy="0 0 0" />
            <geometry>
                <cylinder radius="0.08499999999999996" length="0.0635" />
            </geometry>
        </collision>
        <inertial>
            <origin xyz="0 0 0" rpy="0 0 0" />
            <mass value="2" />
            <inertia ixx="0.019266666666666668" ixy="0" ixz="0" iyy="0.028900000000000006" iyz="0" izz="0.019266666666666668" />
        </inertial>
    </link>

    <joint name="left_wheel_joint" type="continuous">
        <parent link="chassis" />
        <child link="left_wheel" />
        <origin xyz="0 0.18 0" rpy="1.5707963267948963 0 0" />
        <axis xyz="0 0 1"/>
    </joint>

    <gazebo reference="left_wheel">
        <material>Gazebo/White</material>
    </gazebo>

    <!-- RIGHT WHEEL -->

    <link name="right_wheel">
        <visual>
            <origin xyz="0 0 0" rpy="0 0 0" />
            <geometry>
                <cylinder radius="0.085" length="0.0635" />
            </geometry>
            <material name="white"/>
        </visual>
        <collision>
            <origin xyz="0 0 0" rpy="0 0 0" />
            <geometry>
                <cylinder radius="0.085" length="0.0635" />
            </geometry>
        </collision>
        <inertial>
            <origin xyz="0 0 0" rpy="0 0 0" />
            <mass value="1" />
            <inertia ixx="0" ixy="0" ixz="0" iyy="0" iyz="0" izz="0" />
        </inertial>
    </link>

    <joint name="right_wheel_joint" type="continuous">
        <parent link="chassis" />
        <child link="right_wheel" />
        <origin xyz="0 -0.18 0" rpy="1.5707963267948966 0 0.030840783524403125" />
        <axis xyz="0 0 1"/>
    </joint>

    <gazebo reference="right_wheel">
        <material>Gazebo/White</material>
    </gazebo>


</robot>